Workbook

Sheet Rótulos
A1: Necessidade de rótulos – consolidado
A2: B2C = Loja (aba Plano de Produção). B2B = remessas de refil do relatório smartjvg (05/01/2026 a 07/10/2026), por fragrância × concentração × volume. Amarelo = tamanho a definir.
A4: Fragrância | B4: Concentração | C4: Volume (ml) | D4: Frasco | E4: Formato | F4: B2B ou B2C | G4: Quantidades | H4: Tipo Rotulo | I4: Tamanho
A5: Acqua di Gio | B5: Aromatizador de Ambientes | C5: 15 | D5: Pet cristal / válvula spray prata 18/410 | E5: Mini Aromatizador | F5: B2C | G5: 200 | H5: Transparente | I5: 6,5 x 5 cm
A6: Acqua di Gio | B6: Perfume para Ambientes | C6: 250 | D6: Vidro square cristal / tampa difusora prata 28/410 + batoque + varetas | E6: Perfume de Ambientes – Kit Varetas | F6: B2C | G6: 18 | H6: Transparente | I6: 5 x 10 cm (frente e verso)
A7: Acqua di Gio | B7: Perfume para Ambientes | C7: 250 | D7: Pet cilindrico ambar / tampa lacre | E7: Perfume de Ambientes – Refil PET | F7: B2C | G7: 12 | H7: Vinil ou Bopp | I7: 18 x 6,5 cm
A8: Acqua di Gio | B8: Perfume para Ambientes | C8: 250 | D8: Vidro square cristal / válvula spray prata 28/410 | E8: Perfume de Ambientes – Válvula Spray | F8: B2C | G8: 18 | H8: Transparente | I8: 5 x 10 cm (frente e verso)
A9: Alecrim | B9: Fragrância Concentrada | C9: 160 | D9: Pet cilindrico ambar / tampa lacre | E9: Fragrância Concentrada | F9: B2B | G9: 29 | H9: Vinil ou Bopp
A10: Alecrim | B10: Fragrância Concentrada | C10: 400 | D10: Pet cilindrico ambar / tampa lacre | E10: Fragrância Concentrada | F10: B2B | G10: 55 | H10: Vinil ou Bopp | I10: 22 x 8 cm
A11: Alecrim | B11: Fragrância Concentrada | C11: 1000 | D11: Pet cilindrico ambar / tampa lacre | E11: Fragrância Concentrada | F11: B2B | G11: 21 | H11: Vinil ou Bopp | I11: 28 x 10,5 cm
A12: Alecrim | B12: Fragrância Concentrada | C12: 5000 | D12: Pet cilindrico ambar / tampa lacre | E12: Fragrância Concentrada | F12: B2B | G12: 28 | H12: Vinil ou Bopp
A13: Alecrim | B13: Fragrância Ultra Concentrada | C13: 100 | D13: Pet cilindrico ambar / tampa lacre | E13: Fragrância Ultra Concentrada | F13: B2B | G13: 19 | H13: Vinil ou Bopp | I13: 13 x 5 cm
A14: Alecrim | B14: Fragrância Ultra Concentrada | C14: 500 | D14: Pet cilindrico ambar / tampa lacre | E14: Fragrância Ultra Concentrada | F14: B2B | G14: 76 | H14: Vinil ou Bopp | I14: 22 x 8 cm
A15: Alecrim | B15: Aromatizador de Ambientes | C15: 15 | D15: Pet cristal / válvula spray prata 18/410 | E15: Mini Aromatizador | F15: B2C | G15: 100 | H15: Transparente | I15: 6,5 x 5 cm
A16: Alecrim | B16: Aromatizador de Ambientes | C16: 500 | D16: Pet cilindrico ambar / tampa lacre | E16: Aromatizador (Refil) | F16: B2C | G16: 10 | H16: Vinil ou Bopp | I16: 22 x 8 cm
A17: Alecrim | B17: Fragrância Concentrada | C17: 15 | D17: Pet cristal / válvula spray prata 18/410 | E17: Fragrância Concentrada (Refil Equipamento) | F17: B2C | G17: 100 | H17: Transparente | I17: 6,5 x 5 cm
A18: Alecrim | B18: Fragrância Concentrada | C18: 100 | D18: Pet cilindrico ambar / tampa lacre | E18: Fragrância Concentrada (Refil Equipamento) | F18: B2C | G18: 30 | H18: Vinil ou Bopp | I18: 13 x 5 cm
A19: Alecrim | B19: Perfume para Ambientes | C19: 250 | D19: Vidro square cristal / tampa difusora prata 28/410 + batoque + varetas | E19: Perfume de Ambientes – Kit Varetas | F19: B2C | G19: 8 | H19: Transparente | I19: 5 x 10 cm (frente e verso)
A20: Alecrim | B20: Perfume para Ambientes | C20: 250 | D20: Pet cilindrico ambar / tampa lacre | E20: Perfume de Ambientes – Refil PET | F20: B2C | G20: 2 | H20: Vinil ou Bopp | I20: 18 x 6,5 cm
A21: Alecrim | B21: Perfume para Ambientes | C21: 250 | D21: Vidro square cristal / válvula spray prata 28/410 | E21: Perfume de Ambientes – Válvula Spray | F21: B2C | G21: 8 | H21: Transparente | I21: 5 x 10 cm (frente e verso)
A22: Alecrim Sence | B22: Fragrância Concentrada | C22: 400 | D22: Pet cilindrico ambar / tampa lacre | E22: Fragrância Concentrada | F22: B2B | G22: 4 | H22: Vinil ou Bopp | I22: 22 x 8 cm
A23: Alecrim Sence | B23: Fragrância Concentrada | C23: 1000 | D23: Pet cilindrico ambar / tampa lacre | E23: Fragrância Concentrada | F23: B2B | G23: 15 | H23: Vinil ou Bopp | I23: 28 x 10,5 cm
A24: Alecrim Sence | B24: Fragrância Concentrada | C24: 5000 | D24: Pet cilindrico ambar / tampa lacre | E24: Fragrância Concentrada | F24: B2B | G24: 8 | H24: Vinil ou Bopp
A25: Bamboo | B25: Fragrância Concentrada | C25: 400 | D25: Pet cilindrico ambar / tampa lacre | E25: Fragrância Concentrada | F25: B2B | G25: 14 | H25: Vinil ou Bopp | I25: 22 x 8 cm
A26: Bamboo | B26: Fragrância Concentrada | C26: 1000 | D26: Pet cilindrico ambar / tampa lacre | E26: Fragrância Concentrada | F26: B2B | G26: 6 | H26: Vinil ou Bopp | I26: 28 x 10,5 cm
A27: Bamboo | B27: Fragrância Ultra Concentrada | C27: 100 | D27: Pet cilindrico ambar / tampa lacre | E27: Fragrância Ultra Concentrada | F27: B2B | G27: 37 | H27: Vinil ou Bopp | I27: 13 x 5 cm
A28: Bamboo | B28: Fragrância Ultra Concentrada | C28: 500 | D28: Pet cilindrico ambar / tampa lacre | E28: Fragrância Ultra Concentrada | F28: B2B | G28: 43 | H28: Vinil ou Bopp | I28: 22 x 8 cm
A29: Bamboo | B29: Fragrância Ultra Concentrada | C29: 1000 | D29: Pet cilindrico ambar / tampa lacre | E29: Fragrância Ultra Concentrada | F29: B2B | G29: 4 | H29: Vinil ou Bopp | I29: 28 x 10,5 cm
A30: Bamboo | B30: Perfume para Ambientes | C30: 250 | D30: Pet cilindrico ambar / tampa lacre | E30: Perfume para Ambientes | F30: B2B | G30: 36 | H30: Vinil ou Bopp | I30: 18 x 6,5 cm
A31: Bamboo | B31: Aromatizador de Ambientes | C31: 15 | D31: Pet cristal / válvula spray prata 18/410 | E31: Mini Aromatizador | F31: B2C | G31: 100 | H31: Transparente | I31: 6,5 x 5 cm
A32: Bamboo | B32: Aromatizador de Ambientes | C32: 500 | D32: Pet cilindrico ambar / tampa lacre | E32: Aromatizador (Refil) | F32: B2C | G32: 10 | H32: Vinil ou Bopp | I32: 22 x 8 cm
A33: Bamboo | B33: Fragrância Concentrada | C33: 15 | D33: Pet cristal / válvula spray prata 18/410 | E33: Fragrância Concentrada (Refil Equipamento) | F33: B2C | G33: 100 | H33: Transparente | I33: 6,5 x 5 cm
A34: Bamboo | B34: Fragrância Concentrada | C34: 100 | D34: Pet cilindrico ambar / tampa lacre | E34: Fragrância Concentrada (Refil Equipamento) | F34: B2C | G34: 30 | H34: Vinil ou Bopp | I34: 13 x 5 cm
A35: Bamboo | B35: Perfume para Ambientes | C35: 250 | D35: Vidro square cristal / tampa difusora prata 28/410 + batoque + varetas | E35: Perfume de Ambientes – Kit Varetas | F35: B2C | G35: 8 | H35: Transparente | I35: 5 x 10 cm (frente e verso)
A36: Bamboo | B36: Perfume para Ambientes | C36: 250 | D36: Pet cilindrico ambar / tampa lacre | E36: Perfume de Ambientes – Refil PET | F36: B2C | G36: 2 | H36: Vinil ou Bopp | I36: 18 x 6,5 cm
... A62: Citric Bath | B62: Fragrância Concentrada | C62: 1000 | D62: Pet cilindrico ambar / tampa lacre | E62: Fragrância Concentrada | F62: B2B | G62: 18 | H62: Vinil ou Bopp | I62: 28 x 10,5 cm
A63: Citric Bath | B63: Fragrância Concentrada | C63: 5000 | D63: Pet cilindrico ambar / tampa lacre | E63: Fragrância Concentrada | F63: B2B | G63: 8 | H63: Vinil ou Bopp
A64: Citrus Flowers | B64: Fragrância Concentrada | C64: 400 | D64: Pet cilindrico ambar / tampa lacre | E64: Fragrância Concentrada | F64: B2B | G64: 24 | H64: Vinil ou Bopp | I64: 22 x 8 cm
A65: Citrus Flowers | B65: Fragrância Concentrada | C65: 1000 | D65: Pet cilindrico ambar / tampa lacre | E65: Fragrância Concentrada | F65: B2B | G65: 8 | H65: Vinil ou Bopp | I65: 28 x 10,5 cm
A66: Citrus Flowers | B66: Fragrância Ultra Concentrada | C66: 100 | D66: Pet cilindrico ambar / tampa lacre | E66: Fragrância Ultra Concentrada | F66: B2B | G66: 16 | H66: Vinil ou Bopp | I66: 13 x 5 cm
...

Sheet Versões para Orçamento
A1: Versões de rótulo para orçamento – por material, tamanho e canal
A2: Versão = arte única (fragrância × concentração × volume) no mesmo material e tamanho. Fórmulas sobre as abas Por Fragrância e Rótulos.
A4: Material / tipo | B4: Tamanho | C4: Canal | D4: Nº de versões (artes) | E4: Qtd. total de rótulos | F4: Menor tiragem por versão | G4: Maior tiragem por versão | H4: Média por versão | I4: Nº versões se separar formato e canal
A5: Transparente | B5: 5 x 10 cm (frente e verso) | C5: B2C | D5: =COUNTIFS('Por Fragrância'!$D$5:$D$192,$A5,'Por Fragrância'!$E$5:$E$192,$B5,'Por Fragrância'!$G$5:$G$192,$C5) -> 17 | E5: =SUMIFS('Por Fragrância'!$J$5:$J$192,'Por Fragrância'!$D$5:$D$192,$A5,'Por Fragrância'!$E$5:$E$192,$B5,'Por Fragrância'!$G$5:$G$192,$C5) -> 472 | F5: =_xlfn.MINIFS('Por Fragrância'!$J$5:$J$192,'Por Fragrância'!$D$5:$D$192,$A5,'Por Fragrância'!$E$5:$E$192,$B5,'Por Fragrância'!$G$5:$G$192,$C5) -> 16 | G5: =_xlfn.MAXIFS('Por Fragrância'!$J$5:$J$192,'Por Fragrância'!$D$5:$D$192,$A5,'Por Fragrância'!$E$5:$E$192,$B5,'Por Fragrância'!$G$5:$G$192,$C5) -> 36 | H5: =IF(D5=0,0,E5/D5) -> 27.764706 | I5: =COUNTIFS(Rótulos!$H$5:$H$212,$A5,Rótulos!$I$5:$I$212,$B5,Rótulos!$F$5:$F$212,IF($C5="B2B e B2C","~",$C5)) -> 34
A6: Transparente | B6: 6,5 x 5 cm | C6: B2C | D6: =COUNTIFS('Por Fragrância'!$D$5:$D$192,$A6,'Por Fragrância'!$E$5:$E$192,$B6,'Por Fragrância'!$G$5:$G$192,$C6) -> 24 | E6: =SUMIFS('Por Fragrância'!$J$5:$J$192,'Por Fragrância'!$D$5:$D$192,$A6,'Por Fragrância'!$E$5:$E$192,$B6,'Por Fragrância'!$G$5:$G$192,$C6) -> 3400 | F6: =_xlfn.MINIFS('Por Fragrância'!$J$5:$J$192,'Por Fragrância'!$D$5:$D$192,$A6,'Por Fragrância'!$E$5:$E$192,$B6,'Por Fragrância'!$G$5:$G$192,$C6) -> 100 | G6: =_xlfn.MAXIFS('Por Fragrância'!$J$5:$J$192,'Por Fragrância'!$D$5:$D$192,$A6,'Por Fragrância'!$E$5:$E$192,$B6,'Por Fragrância'!$G$5:$G$192,$C6) -> 200 | H6: =IF(D6=0,0,E6/D6) -> 141.66667 | I6: =COUNTIFS(Rótulos!$H$5:$H$212,$A6,Rótulos!$I$5:$I$212,$B6,Rótulos!$F$5:$F$212,IF($C6="B2B e B2C","~",$C6)) -> 24
A7: Vinil ou Bopp | B7: 13 x 5 cm | C7: B2B | D7: =COUNTIFS('Por Fragrância'!$D$5:$D$192,$A7,'Por Fragrância'!$E$5:$E$192,$B7,'Por Fragrância'!$G$5:$G$192,$C7) -> 23 | E7: =SUMIFS('Por Fragrância'!$J$5:$J$192,'Por Fragrância'!$D$5:$D$192,$A7,'Por Fragrância'!$E$5:$E$192,$B7,'Por Fragrância'!$G$5:$G$192,$C7) -> 1307 | F7: =_xlfn.MINIFS('Por Fragrância'!$J$5:$J$192,'Por Fragrância'!$D$5:$D$192,$A7,'Por Fragrância'!$E$5:$E$192,$B7,'Por Fragrância'!$G$5:$G$192,$C7) -> 2 | G7: =_xlfn.MAXIFS('Por Fragrância'!$J$5:$J$192,'Por Fragrância'!$D$5:$D$192,$A7,'Por Fragrância'!$E$5:$E$192,$B7,'Por Fragrância'!$G$5:$G$192,$C7) -> 649 | H7: =IF(D7=0,0,E7/D7) -> 56.826087 | I7: =COUNTIFS(Rótulos!$H$5:$H$212,$A7,Rótulos!$I$5:$I$212,$B7,Rótulos!$F$5:$F$212,IF($C7="B2B e B2C","~",$C7)) -> 23
A8: Vinil ou Bopp | B8: 13 x 5 cm | C8: B2C | D8: =COUNTIFS('Por Fragrância'!$D$5:$D$192,$A8,'Por Fragrância'!$E$5:$E$192,$B8,'Por Fragrância'!$G$5:$G$192,$C8) -> 8 | E8: =SUMIFS('Por Fragrância'!$J$5:$J$192,'Por Fragrância'!$D$5:$D$192,$A8,'Por Fragrância'!$E$5:$E$192,$B8,'Por Fragrância'!$G$5:$G$192,$C8) -> 360 | F8: =_xlfn.MINIFS('Por Fragrância'!$J$5:$J$192,'Por Fragrância'!$D$5:$D$192,$A8,'Por Fragrância'!$E$5:$E$192,$B8,'Por Fragrância'!$G$5:$G$192,$C8) -> 30 | G8: =_xlfn.MAXIFS('Por Fragrância'!$J$5:$J$192,'Por Fragrância'!$D$5:$D$192,$A8,'Por Fragrância'!$E$5:$E$192,$B8,'Por Fragrância'!$G$5:$G$192,$C8) -> 150 | H8: =IF(D8=0,0,E8/D8) -> 45 | I8: =COUNTIFS(Rótulos!$H$5:$H$212,$A8,Rótulos!$I$5:$I$212,$B8,Rótulos!$F$5:$F$212,IF($C8="B2B e B2C","~",$C8)) -> 8
A9: Vinil ou Bopp | B9: 18 x 6,5 cm | C9: B2B | D9: =COUNTIFS('Por Fragrância'!$D$5:$D$192,$A9,'Por Fragrância'!$E$5:$E$192,$B9,'Por Fragrância'!$G$5:$G$192,$C9) -> 11 | E9: =SUMIFS('Por Fragrância'!$J$5:$J$192,'Por Fragrância'!$D$5:$D$192,$A9,'Por Fragrância'!$E$5:$E$192,$B9,'Por Fragrância'!$G$5:$G$192,$C9) -> 481 | F9: =_xlfn.MINIFS('Por Fragrância'!$J$5:$J$192,'Por Fragrância'!$D$5:$D$192,$A9,'Por Fragrância'!$E$5:$E$192,$B9,'Por Fragrância'!$G$5:$G$192,$C9) -> 4 | G9: =_xlfn.MAXIFS('Por Fragrância'!$J$5:$J$192,'Por Fragrância'!$D$5:$D$192,$A9,'Por Fragrância'!$E$5:$E$192,$B9,'Por Fragrância'!$G$5:$G$192,$C9) -> 205 | H9: =IF(D9=0,0,E9/D9) -> 43.727273 | I9: =COUNTIFS(Rótulos!$H$5:$H$212,$A9,Rótulos!$I$5:$I$212,$B9,Rótulos!$F$5:$F$212,IF($C9="B2B e B2C","~",$C9)) -> 13
A10: Vinil ou Bopp | B10: 18 x 6,5 cm | C10: B2B e B2C | D10: =COUNTIFS('Por Fragrância'!$D$5:$D$192,$A10,'Por Fragrância'!$E$5:$E$192,$B10,'Por Fragrância'!$G$5:$G$192,$C10) -> 2 | E10: =SUMIFS('Por Fragrância'!$J$5:$J$192,'Por Fragrância'!$D$5:$D$192,$A10,'Por Fragrância'!$E$5:$E$192,$B10,'Por Fragrância'!$G$5:$G$192,$C10) -> 120 | F10: =_xlfn.MINIFS('Por Fragrância'!$J$5:$J$192,'Por Fragrância'!$D$5:$D$192,$A10,'Por Fragrância'!$E$5:$E$192,$B10,'Por Fragrância'!$G$5:$G$192,$C10) -> 38 | G10: =_xlfn.MAXIFS('Por Fragrância'!$J$5:$J$192,'Por Fragrância'!$D$5:$D$192,$A10,'Por Fragrância'!$E$5:$E$192,$B10,'Por Fragrância'!$G$5:$G$192,$C10) -> 82 | H10: =IF(D10=0,0,E10/D10) -> 60 | I10: =COUNTIFS(Rótulos!$H$5:$H$212,$A10,Rótulos!$I$5:$I$212,$B10,Rótulos!$F$5:$F$212,IF($C10="B2B e B2C","~",$C10)) -> 0
A11: Vinil ou Bopp | B11: 18 x 6,5 cm | C11: B2C | D11: =COUNTIFS('Por Fragrância'!$D$5:$D$192,$A11,'Por Fragrância'!$E$5:$E$192,$B11,'Por Fragrância'!$G$5:$G$192,$C11) -> 15 | E11: =SUMIFS('Por Fragrância'!$J$5:$J$192,'Por Fragrância'!$D$5:$D$192,$A11,'Por Fragrância'!$E$5:$E$192,$B11,'Por Fragrância'!$G$5:$G$192,$C11) -> 130 | F11: =_xlfn.MINIFS('Por Fragrância'!$J$5:$J$192,'Por Fragrância'!$D$5:$D$192,$A11,'Por Fragrância'!$E$5:$E$192,$B11,'Por Fragrância'!$G$5:$G$192,$C11) -> 2 | G11: =_xlfn.MAXIFS('Por Fragrância'!$J$5:$J$192,'Por Fragrância'!$D$5:$D$192,$A11,'Por Fragrância'!$E$5:$E$192,$B11,'Por Fragrância'!$G$5:$G$192,$C11) -> 12 | H11: =IF(D11=0,0,E11/D11) -> 8.6666667 | I11: =COUNTIFS(Rótulos!$H$5:$H$212,$A11,Rótulos!$I$5:$I$212,$B11,Rótulos!$F$5:$F$212,IF($C11="B2B e B2C","~",$C11)) -> 17
A12: Vinil ou Bopp | B12: 22 x 8 cm | C12: B2B | D12: =COUNTIFS('Por Fragrância'!$D$5:$D$192,$A12,'Por Fragrância'!$E$5:$E$192,$B12,'Por Fragrância'!$G$5:$G$192,$C12) -> 53 | E12: =SUMIFS('Por Fragrância'!$J$5:$J$192,'Por Fragrância'!$D$5:$D$192,$A12,'Por Fragrância'!$E$5:$E$192,$B12,'Por Fragrância'!$G$5:$G$192,$C12) -> 1614 | F12: =_xlfn.MINIFS('Por Fragrância'!$J$5:$J$192,'Por Fragrância'!$D$5:$D$192,$A12,'Por Fragrância'!$E$5:$E$192,$B12,'Por Fragrância'!$G$5:$G$192,$C12) -> 1 | G12: =_xlfn.MAXIFS('Por Fragrância'!$J$5:$J$192,'Por Fragrância'!$D$5:$D$192,$A12,'Por Fragrância'!$E$5:$E$192,$B12,'Por Fragrância'!$G$5:$G$192,$C12) -> 379 | H12: =IF(D12=0,0,E12/D12) -> 30.45283 | I12: =COUNTIFS(Rótulos!$H$5:$H$212,$A12,Rótulos!$I$5:$I$212,$B12,Rótulos!$F$5:$F$212,IF($C12="B2B e B2C","~",$C12)) -> 54
A13: Vinil ou Bopp | B13: 22 x 8 cm | C13: B2B e B2C | D13: =COUNTIFS('Por Fragrância'!$D$5:$D$192,$A13,'Por Fragrância'!$E$5:$E$192,$B13,'Por Fragrância'!$G$5:$G$192,$C13) -> 1 | E13: =SUMIFS('Por Fragrância'!$J$5:$J$192,'Por Fragrância'!$D$5:$D$192,$A13,'Por Fragrância'!$E$5:$E$192,$B13,'Por Fragrância'!$G$5:$G$192,$C13) -> 50 | F13: =_xlfn.MINIFS('Por Fragrância'!$J$5:$J$192,'Por Fragrância'!$D$5:$D$192,$A13,'Por Fragrância'!$E$5:$E$192,$B13,'Por Fragrância'!$G$5:$G$192,$C13) -> 50 | G13: =_xlfn.MAXIFS('Por Fragrância'!$J$5:$J$192,'Por Fragrância'!$D$5:$D$192,$A13,'Por Fragrância'!$E$5:$E$192,$B13,'Por Fragrância'!$G$5:$G$192,$C13) -> 50 | H13: =IF(D13=0,0,E13/D13) -> 50 | I13: =COUNTIFS(Rótulos!$H$5:$H$212,$A13,Rótulos!$I$5:$I$212,$B13,Rótulos!$F$5:$F$212,IF($C13="B2B e B2C","~",$C13)) -> 0
A14: Vinil ou Bopp | B14: 22 x 8 cm | C14: B2C | D14: =COUNTIFS('Por Fragrância'!$D$5:$D$192,$A14,'Por Fragrância'!$E$5:$E$192,$B14,'Por Fragrância'!$G$5:$G$192,$C14) -> 6 | E14: =SUMIFS('Por Fragrância'!$J$5:$J$192,'Por Fragrância'!$D$5:$D$192,$A14,'Por Fragrância'!$E$5:$E$192,$B14,'Por Fragrância'!$G$5:$G$192,$C14) -> 60 | F14: =_xlfn.MINIFS('Por Fragrância'!$J$5:$J$192,'Por Fragrância'!$D$5:$D$192,$A14,'Por Fragrância'!$E$5:$E$192,$B14,'Por Fragrância'!$G$5:$G$192,$C14) -> 10 | G14: =_xlfn.MAXIFS('Por Fragrância'!$J$5:$J$192,'Por Fragrância'!$D$5:$D$192,$A14,'Por Fragrância'!$E$5:$E$192,$B14,'Por Fragrância'!$G$5:$G$192,$C14) -> 10 | H14: =IF(D14=0,0,E14/D14) -> 10 | I14: =COUNTIFS(Rótulos!$H$5:$H$212,$A14,Rótulos!$I$5:$I$212,$B14,Rótulos!$F$5:$F$212,IF($C14="B2B e B2C","~",$C14)) -> 7
A15: Vinil ou Bopp | B15: 28 x 10,5 cm | C15: B2B | D15: =COUNTIFS('Por Fragrância'!$D$5:$D$192,$A15,'Por Fragrância'!$E$5:$E$192,$B15,'Por Fragrância'!$G$5:$G$192,$C15) -> 18 | E15: =SUMIFS('Por Fragrância'!$J$5:$J$192,'Por Fragrância'!$D$5:$D$192,$A15,'Por Fragrância'!$E$5:$E$192,$B15,'Por Fragrância'!$G$5:$G$192,$C15) -> 197 | F15: =_xlfn.MINIFS('Por Fragrância'!$J$5:$J$192,'Por Fragrância'!$D$5:$D$192,$A15,'Por Fragrância'!$E$5:$E$192,$B15,'Por Fragrância'!$G$5:$G$192,$C15) -> 2 | G15: =_xlfn.MAXIFS('Por Fragrância'!$J$5:$J$192,'Por Fragrância'!$D$5:$D$192,$A15,'Por Fragrância'!$E$5:$E$192,$B15,'Por Fragrância'!$G$5:$G$192,$C15) -> 22 | H15: =IF(D15=0,0,E15/D15) -> 10.944444 | I15: =COUNTIFS(Rótulos!$H$5:$H$212,$A15,Rótulos!$I$5:$I$212,$B15,Rótulos!$F$5:$F$212,IF($C15="B2B e B2C","~",$C15)) -> 18
A16: Vinil ou Bopp | B16: A definir | C16: B2B | D16: =COUNTIFS('Por Fragrância'!$D$5:$D$192,$A16,'Por Fragrância'!$E$5:$E$192,$B16,'Por Fragrância'!$G$5:$G$192,$C16) -> 10 | E16: =SUMIFS('Por Fragrância'!$J$5:$J$192,'Por Fragrância'!$D$5:$D$192,$A16,'Por Fragrância'!$E$5:$E$192,$B16,'Por Fragrância'!$G$5:$G$192,$C16) -> 141 | F16: =_xlfn.MINIFS('Por Fragrância'!$J$5:$J$192,'Por Fragrância'!$D$5:$D$192,$A16,'Por Fragrância'!$E$5:$E$192,$B16,'Por Fragrância'!$G$5:$G$192,$C16) -> 2 | G16: =_xlfn.MAXIFS('Por Fragrância'!$J$5:$J$192,'Por Fragrância'!$D$5:$D$192,$A16,'Por Fragrância'!$E$5:$E$192,$B16,'Por Fragrância'!$G$5:$G$192,$C16) -> 29 | H16: =IF(D16=0,0,E16/D16) -> 14.1 | I16: =SUMPRODUCT((Rótulos!$H$5:$H$212=$A16)*(Rótulos!$I$5:$I$212="")*(Rótulos!$F$5:$F$212=IF($C16="B2B e B2C","~",$C16))) -> 10
A17: Total | D17: =SUM(D5:D16) -> 188 | E17: =SUM(E5:E16) -> 8332 | I17: =COUNTA(Rótulos!$A$5:$A$212) -> 208
A19: Resumo por material e tamanho (todos os canais)
A20: Material / tipo | B20: Tamanho | C20: Nº de versões (artes) | D20: Qtd. total de rótulos
A21: Transparente | B21: 5 x 10 cm (frente e verso) | C21: =COUNTIFS('Por Fragrância'!$D$5:$D$192,$A21,'Por Fragrância'!$E$5:$E$192,$B21) -> 17 | D21: =SUMIFS('Por Fragrância'!$J$5:$J$192,'Por Fragrância'!$D$5:$D$192,$A21,'Por Fragrância'!$E$5:$E$192,$B21) -> 472
A22: Transparente | B22: 6,5 x 5 cm | C22: =COUNTIFS('Por Fragrância'!$D$5:$D$192,$A22,'Por Fragrância'!$E$5:$E$192,$B22) -> 24 | D22: =SUMIFS('Por Fragrância'!$J$5:$J$192,'Por Fragrância'!$D$5:$D$192,$A22,'Por Fragrância'!$E$5:$E$192,$B22) -> 3400
A23: Vinil ou Bopp | B23: 13 x 5 cm | C23: =COUNTIFS('Por Fragrância'!$D$5:$D$192,$A23,'Por Fragrância'!$E$5:$E$192,$B23) -> 31 | D23: =SUMIFS('Por Fragrância'!$J$5:$J$192,'Por Fragrância'!$D$5:$D$192,$A23,'Por Fragrância'!$E$5:$E$192,$B23) -> 1667
A24: Vinil ou Bopp | B24: 18 x 6,5 cm | C24: =COUNTIFS('Por Fragrância'!$D$5:$D$192,$A24,'Por Fragrância'!$E$5:$E$192,$B24) -> 28 | D24: =SUMIFS('Por Fragrância'!$J$5:$J$192,'Por Fragrância'!$D$5:$D$192,$A24,'Por Fragrância'!$E$5:$E$192,$B24) -> 731
A25: Vinil ou Bopp | B25: 22 x 8 cm | C25: =COUNTIFS('Por Fragrância'!$D$5:$D$192,$A25,'Por Fragrância'!$E$5:$E$192,$B25) -> 60 | D25: =SUMIFS('Por Fragrância'!$J$5:$J$192,'Por Fragrância'!$D$5:$D$192,$A25,'Por Fragrância'!$E$5:$E$192,$B25) -> 1724
A26: Vinil ou Bopp | B26: 28 x 10,5 cm | C26: =COUNTIFS('Por Fragrância'!$D$5:$D$192,$A26,'Por Fragrância'!$E$5:$E$192,$B26) -> 18 | D26: =SUMIFS('Por Fragrância'!$J$5:$J$192,'Por Fragrância'!$D$5:$D$192,$A26,'Por Fragrância'!$E$5:$E$192,$B26) -> 197
A27: Vinil ou Bopp | B27: A definir | C27: =COUNTIFS('Por Fragrância'!$D$5:$D$192,$A27,'Por Fragrância'!$E$5:$E$192,$B27) -> 10 | D27: =SUMIFS('Por Fragrância'!$J$5:$J$192,'Por Fragrância'!$D$5:$D$192,$A27,'Por Fragrância'!$E$5:$E$192,$B27) -> 141
A28: Total | C28: =SUM(C21:C27) -> 188 | D28: =SUM(D21:D27) -> 8332
A30: "Nº versões se separar formato e canal": conta cada linha da aba Rótulos como arte própria (ex.: Válvula Spray e Kit Varetas com artes diferentes; mesmo rótulo B2B e B2C com artes diferentes). Linhas "B2B e B2C" mostram "-" nessa coluna porque já estão contadas nas linhas B2B e B2C.
A31: Rótulo 5 x 10 cm (frente e verso): quantidade = nº de frascos; se forem 2 rótulos por frasco, dobrar no orçamento.

Sheet Por Fragrância
A1: Quantidades por fragrância × concentração × volume
A2: Soma linhas com mesma fragrância, concentração, volume, tipo e tamanho de rótulo. Fórmulas sobre a aba Rótulos.
A4: Fragrância | B4: Concentração | C4: Volume (ml) | D4: Tipo Rotulo | E4: Tamanho | F4: Formatos agrupados | G4: Canal | H4: Qtd. B2C | I4: Qtd. B2B | J4: Quantidade total
A5: Acqua di Gio | B5: Aromatizador de Ambientes | C5: 15 | D5: Transparente | E5: 6,5 x 5 cm | F5: Mini Aromatizador | G5: B2C | H5: =SUMIFS(Rótulos!$G$5:$G$212,Rótulos!$A$5:$A$212,$A5,Rótulos!$B$5:$B$212,$B5,Rótulos!$C$5:$C$212,$C5,Rótulos!$H$5:$H$212,$D5,Rótulos!$I$5:$I$212,$E5,Rótulos!$F$5:$F$212,"B2C") -> 200 | I5: =SUMIFS(Rótulos!$G$5:$G$212,Rótulos!$A$5:$A$212,$A5,Rótulos!$B$5:$B$212,$B5,Rótulos!$C$5:$C$212,$C5,Rótulos!$H$5:$H$212,$D5,Rótulos!$I$5:$I$212,$E5,Rótulos!$F$5:$F$212,"B2B") -> 0 | J5: =H5+I5 -> 200
A6: Acqua di Gio | B6: Perfume para Ambientes | C6: 250 | D6: Transparente | E6: 5 x 10 cm (frente e verso) | F6: Perfume de Ambientes – Kit Varetas + Perfume de Ambientes – Válvula Spray | G6: B2C | H6: =SUMIFS(Rótulos!$G$5:$G$212,Rótulos!$A$5:$A$212,$A6,Rótulos!$B$5:$B$212,$B6,Rótulos!$C$5:$C$212,$C6,Rótulos!$H$5:$H$212,$D6,Rótulos!$I$5:$I$212,$E6,Rótulos!$F$5:$F$212,"B2C") -> 36 | I6: =SUMIFS(Rótulos!$G$5:$G$212,Rótulos!$A$5:$A$212,$A6,Rótulos!$B$5:$B$212,$B6,Rótulos!$C$5:$C$212,$C6,Rótulos!$H$5:$H$212,$D6,Rótulos!$I$5:$I$212,$E6,Rótulos!$F$5:$F$212,"B2B") -> 0 | J6: =H6+I6 -> 36
A7: Acqua di Gio | B7: Perfume para Ambientes | C7: 250 | D7: Vinil ou Bopp | E7: 18 x 6,5 cm | F7: Perfume de Ambientes – Refil PET | G7: B2C | H7: =SUMIFS(Rótulos!$G$5:$G$212,Rótulos!$A$5:$A$212,$A7,Rótulos!$B$5:$B$212,$B7,Rótulos!$C$5:$C$212,$C7,Rótulos!$H$5:$H$212,$D7,Rótulos!$I$5:$I$212,$E7,Rótulos!$F$5:$F$212,"B2C") -> 12 | I7: =SUMIFS(Rótulos!$G$5:$G$212,Rótulos!$A$5:$A$212,$A7,Rótulos!$B$5:$B$212,$B7,Rótulos!$C$5:$C$212,$C7,Rótulos!$H$5:$H$212,$D7,Rótulos!$I$5:$I$212,$E7,Rótulos!$F$5:$F$212,"B2B") -> 0 | J7: =H7+I7 -> 12
A8: Alecrim | B8: Fragrância Concentrada | C8: 160 | D8: Vinil ou Bopp | E8: A definir | F8: Fragrância Concentrada | G8: B2B | H8: =SUMIFS(Rótulos!$G$5:$G$212,Rótulos!$A$5:$A$212,$A8,Rótulos!$B$5:$B$212,$B8,Rótulos!$C$5:$C$212,$C8,Rótulos!$H$5:$H$212,$D8,Rótulos!$I$5:$I$212,"=",Rótulos!$F$5:$F$212,"B2C") -> 0 | I8: =SUMIFS(Rótulos!$G$5:$G$212,Rótulos!$A$5:$A$212,$A8,Rótulos!$B$5:$B$212,$B8,Rótulos!$C$5:$C$212,$C8,Rótulos!$H$5:$H$212,$D8,Rótulos!$I$5:$I$212,"=",Rótulos!$F$5:$F$212,"B2B") -> 29 | J8: =H8+I8 -> 29
A9: Alecrim | B9: Fragrância Concentrada | C9: 400 | D9: Vinil ou Bopp | E9: 22 x 8 cm | F9: Fragrância Concentrada | G9: B2B | H9: =SUMIFS(Rótulos!$G$5:$G$212,Rótulos!$A$5:$A$212,$A9,Rótulos!$B$5:$B$212,$B9,Rótulos!$C$5:$C$212,$C9,Rótulos!$H$5:$H$212,$D9,Rótulos!$I$5:$I$212,$E9,Rótulos!$F$5:$F$212,"B2C") -> 0 | I9: =SUMIFS(Rótulos!$G$5:$G$212,Rótulos!$A$5:$A$212,$A9,Rótulos!$B$5:$B$212,$B9,Rótulos!$C$5:$C$212,$C9,Rótulos!$H$5:$H$212,$D9,Rótulos!$I$5:$I$212,$E9,Rótulos!$F$5:$F$212,"B2B") -> 55 | J9: =H9+I9 -> 55
A10: Alecrim | B10: Fragrância Concentrada | C10: 1000 | D10: Vinil ou Bopp | E10: 28 x 10,5 cm | F10: Fragrância Concentrada | G10: B2B | H10: =SUMIFS(Rótulos!$G$5:$G$212,Rótulos!$A$5:$A$212,$A10,Rótulos!$B$5:$B$212,$B10,Rótulos!$C$5:$C$212,$C10,Rótulos!$H$5:$H$212,$D10,Rótulos!$I$5:$I$212,$E10,Rótulos!$F$5:$F$212,"B2C") -> 0 | I10: =SUMIFS(Rótulos!$G$5:$G$212,Rótulos!$A$5:$A$212,$A10,Rótulos!$B$5:$B$212,$B10,Rótulos!$C$5:$C$212,$C10,Rótulos!$H$5:$H$212,$D10,Rótulos!$I$5:$I$212,$E10,Rótulos!$F$5:$F$212,"B2B") -> 21 | J10: =H10+I10 -> 21
A11: Alecrim | B11: Fragrância Concentrada | C11: 5000 | D11: Vinil ou Bopp | E11: A definir | F11: Fragrância Concentrada | G11: B2B | H11: =SUMIFS(Rótulos!$G$5:$G$212,Rótulos!$A$5:$A$212,$A11,Rótulos!$B$5:$B$212,$B11,Rótulos!$C$5:$C$212,$C11,Rótulos!$H$5:$H$212,$D11,Rótulos!$I$5:$I$212,"=",Rótulos!$F$5:$F$212,"B2C") -> 0 | I11: =SUMIFS(Rótulos!$G$5:$G$212,Rótulos!$A$5:$A$212,$A11,Rótulos!$B$5:$B$212,$B11,Rótulos!$C$5:$C$212,$C11,Rótulos!$H$5:$H$212,$D11,Rótulos!$I$5:$I$212,"=",Rótulos!$F$5:$F$212,"B2B") -> 28 | J11: =H11+I11 -> 28
A12: Alecrim | B12: Fragrância Ultra Concentrada | C12: 100 | D12: Vinil ou Bopp | E12: 13 x 5 cm | F12: Fragrância Ultra Concentrada | G12: B2B | H12: =SUMIFS(Rótulos!$G$5:$G$212,Rótulos!$A$5:$A$212,$A12,Rótulos!$B$5:$B$212,$B12,Rótulos!$C$5:$C$212,$C12,Rótulos!$H$5:$H$212,$D12,Rótulos!$I$5:$I$212,$E12,Rótulos!$F$5:$F$212,"B2C") -> 0 | I12: =SUMIFS(Rótulos!$G$5:$G$212,Rótulos!$A$5:$A$212,$A12,Rótulos!$B$5:$B$212,$B12,Rótulos!$C$5:$C$212,$C12,Rótulos!$H$5:$H$212,$D12,Rótulos!$I$5:$I$212,$E12,Rótulos!$F$5:$F$212,"B2B") -> 19 | J12: =H12+I12 -> 19
A13: Alecrim | B13: Fragrância Ultra Concentrada | C13: 500 | D13: Vinil ou Bopp | E13: 22 x 8 cm | F13: Fragrância Ultra Concentrada | G13: B2B | H13: =SUMIFS(Rótulos!$G$5:$G$212,Rótulos!$A$5:$A$212,$A13,Rótulos!$B$5:$B$212,$B13,Rótulos!$C$5:$C$212,$C13,Rótulos!$H$5:$H$212,$D13,Rótulos!$I$5:$I$212,$E13,Rótulos!$F$5:$F$212,"B2C") -> 0 | I13: =SUMIFS(Rótulos!$G$5:$G$212,Rótulos!$A$5:$A$212,$A13,Rótulos!$B$5:$B$212,$B13,Rótulos!$C$5:$C$212,$C13,Rótulos!$H$5:$H$212,$D13,Rótulos!$I$5:$I$212,$E13,Rótulos!$F$5:$F$212,"B2B") -> 76 | J13: =H13+I13 -> 76
A14: Alecrim | B14: Aromatizador de Ambientes | C14: 15 | D14: Transparente | E14: 6,5 x 5 cm | F14: Mini Aromatizador | G14: B2C | H14: =SUMIFS(Rótulos!$G$5:$G$212,Rótulos!$A$5:$A$212,$A14,Rótulos!$B$5:$B$212,$B14,Rótulos!$C$5:$C$212,$C14,Rótulos!$H$5:$H$212,$D14,Rótulos!$I$5:$I$212,$E14,Rótulos!$F$5:$F$212,"B2C") -> 100 | I14: =SUMIFS(Rótulos!$G$5:$G$212,Rótulos!$A$5:$A$212,$A14,Rótulos!$B$5:$B$212,$B14,Rótulos!$C$5:$C$212,$C14,Rótulos!$H$5:$H$212,$D14,Rótulos!$I$5:$I$212,$E14,Rótulos!$F$5:$F$212,"B2B") -> 0 | J14: =H14+I14 -> 100
A15: Alecrim | B15: Aromatizador de Ambientes | C15: 500 | D15: Vinil ou Bopp | E15: 22 x 8 cm | F15: Aromatizador (Refil) | G15: B2C | H15: =SUMIFS(Rótulos!$G$5:$G$212,Rótulos!$A$5:$A$212,$A15,Rótulos!$B$5:$B$212,$B15,Rótulos!$C$5:$C$212,$C15,Rótulos!$H$5:$H$212,$D15,Rótulos!$I$5:$I$212,$E15,Rótulos!$F$5:$F$212,"B2C") -> 10 | I15: =SUMIFS(Rótulos!$G$5:$G$212,Rótulos!$A$5:$A$212,$A15,Rótulos!$B$5:$B$212,$B15,Rótulos!$C$5:$C$212,$C15,Rótulos!$H$5:$H$212,$D15,Rótulos!$I$5:$I$212,$E15,Rótulos!$F$5:$F$212,"B2B") -> 0 | J15: =H15+I15 -> 10
A16: Alecrim | B16: Fragrância Concentrada | C16: 15 | D16: Transparente | E16: 6,5 x 5 cm | F16: Fragrância Concentrada (Refil Equipamento) | G16: B2C | H16: =SUMIFS(Rótulos!$G$5:$G$212,Rótulos!$A$5:$A$212,$A16,Rótulos!$B$5:$B$212,$B16,Rótulos!$C$5:$C$212,$C16,Rótulos!$H$5:$H$212,$D16,Rótulos!$I$5:$I$212,$E16,Rótulos!$F$5:$F$212,"B2C") -> 100 | I16: =SUMIFS(Rótulos!$G$5:$G$212,Rótulos!$A$5:$A$212,$A16,Rótulos!$B$5:$B$212,$B16,Rótulos!$C$5:$C$212,$C16,Rótulos!$H$5:$H$212,$D16,Rótulos!$I$5:$I$212,$E16,Rótulos!$F$5:$F$212,"B2B") -> 0 | J16: =H16+I16 -> 100
A17: Alecrim | B17: Fragrância Concentrada | C17: 100 | D17: Vinil ou Bopp | E17: 13 x 5 cm | F17: Fragrância Concentrada (Refil Equipamento) | G17: B2C | H17: =SUMIFS(Rótulos!$G$5:$G$212,Rótulos!$A$5:$A$212,$A17,Rótulos!$B$5:$B$212,$B17,Rótulos!$C$5:$C$212,$C17,Rótulos!$H$5:$H$212,$D17,Rótulos!$I$5:$I$212,$E17,Rótulos!$F$5:$F$212,"B2C") -> 30 | I17: =SUMIFS(Rótulos!$G$5:$G$212,Rótulos!$A$5:$A$212,$A17,Rótulos!$B$5:$B$212,$B17,Rótulos!$C$5:$C$212,$C17,Rótulos!$H$5:$H$212,$D17,Rótulos!$I$5:$I$212,$E17,Rótulos!$F$5:$F$212,"B2B") -> 0 | J17: =H17+I17 -> 30
A18: Alecrim | B18: Perfume para Ambientes | C18: 250 | D18: Transparente | E18: 5 x 10 cm (frente e verso) | F18: Perfume de Ambientes – Kit Varetas + Perfume de Ambientes – Válvula Spray | G18: B2C | H18: =SUMIFS(Rótulos!$G$5:$G$212,Rótulos!$A$5:$A$212,$A18,Rótulos!$B$5:$B$212,$B18,Rótulos!$C$5:$C$212,$C18,Rótulos!$H$5:$H$212,$D18,Rótulos!$I$5:$I$212,$E18,Rótulos!$F$5:$F$212,"B2C") -> 16 | I18: =SUMIFS(Rótulos!$G$5:$G$212,Rótulos!$A$5:$A$212,$A18,Rótulos!$B$5:$B$212,$B18,Rótulos!$C$5:$C$212,$C18,Rótulos!$H$5:$H$212,$D18,Rótulos!$I$5:$I$212,$E18,Rótulos!$F$5:$F$212,"B2B") -> 0 | J18: =H18+I18 -> 16
A19: Alecrim | B19: Perfume para Ambientes | C19: 250 | D19: Vinil ou Bopp | E19: 18 x 6,5 cm | F19: Perfume de Ambientes – Refil PET | G19: B2C | H19: =SUMIFS(Rótulos!$G$5:$G$212,Rótulos!$A$5:$A$212,$A19,Rótulos!$B$5:$B$212,$B19,Rótulos!$C$5:$C$212,$C19,Rótulos!$H$5:$H$212,$D19,Rótulos!$I$5:$I$212,$E19,Rótulos!$F$5:$F$212,"B2C") -> 2 | I19: =SUMIFS(Rótulos!$G$5:$G$212,Rótulos!$A$5:$A$212,$A19,Rótulos!$B$5:$B$212,$B19,Rótulos!$C$5:$C$212,$C19,Rótulos!$H$5:$H$212,$D19,Rótulos!$I$5:$I$212,$E19,Rótulos!$F$5:$F$212,"B2B") -> 0 | J19: =H19+I19 -> 2
A20: Alecrim Sence | B20: Fragrância Concentrada | C20: 400 | D20: Vinil ou Bopp | E20: 22 x 8 cm | F20: Fragrância Concentrada | G20: B2B | H20: =SUMIFS(Rótulos!$G$5:$G$212,Rótulos!$A$5:$A$212,$A20,Rótulos!$B$5:$B$212,$B20,Rótulos!$C$5:$C$212,$C20,Rótulos!$H$5:$H$212,$D20,Rótulos!$I$5:$I$212,$E20,Rótulos!$F$5:$F$212,"B2C") -> 0 | I20: =SUMIFS(Rótulos!$G$5:$G$212,Rótulos!$A$5:$A$212,$A20,Rótulos!$B$5:$B$212,$B20,Rótulos!$C$5:$C$212,$C20,Rótulos!$H$5:$H$212,$D20,Rótulos!$I$5:$I$212,$E20,Rótulos!$F$5:$F$212,"B2B") -> 4 | J20: =H20+I20 -> 4
A21: Alecrim Sence | B21: Fragrância Concentrada | C21: 1000 | D21: Vinil ou Bopp | E21: 28 x 10,5 cm | F21: Fragrância Concentrada | G21: B2B | H21: =SUMIFS(Rótulos!$G$5:$G$212,Rótulos!$A$5:$A$212,$A21,Rótulos!$B$5:$B$212,$B21,Rótulos!$C$5:$C$212,$C21,Rótulos!$H$5:$H$212,$D21,Rótulos!$I$5:$I$212,$E21,Rótulos!$F$5:$F$212,"B2C") -> 0 | I21: =SUMIFS(Rótulos!$G$5:$G$212,Rótulos!$A$5:$A$212,$A21,Rótulos!$B$5:$B$212,$B21,Rótulos!$C$5:$C$212,$C21,Rótulos!$H$5:$H$212,$D21,Rótulos!$I$5:$I$212,$E21,Rótulos!$F$5:$F$212,"B2B") -> 15 | J21: =H21+I21 -> 15
A22: Alecrim Sence | B22: Fragrância Concentrada | C22: 5000 | D22: Vinil ou Bopp | E22: A definir | F22: Fragrância Concentrada | G22: B2B | H22: =SUMIFS(Rótulos!$G$5:$G$212,Rótulos!$A$5:$A$212,$A22,Rótulos!$B$5:$B$212,$B22,Rótulos!$C$5:$C$212,$C22,Rótulos!$H$5:$H$212,$D22,Rótulos!$I$5:$I$212,"=",Rótulos!$F$5:$F$212,"B2C") -> 0 | I22: =SUMIFS(Rótulos!$G$5:$G$212,Rótulos!$A$5:$A$212,$A22,Rótulos!$B$5:$B$212,$B22,Rótulos!$C$5:$C$212,$C22,Rótulos!$H$5:$H$212,$D22,Rótulos!$I$5:$I$212,"=",Rótulos!$F$5:$F$212,"B2B") -> 8 | J22: =H22+I22 -> 8
A23: Bamboo | B23: Fragrância Concentrada | C23: 400 | D23: Vinil ou Bopp | E23: 22 x 8 cm | F23: Fragrância Concentrada | G23: B2B | H23: =SUMIFS(Rótulos!$G$5:$G$212,Rótulos!$A$5:$A$212,$A23,Rótulos!$B$5:$B$212,$B23,Rótulos!$C$5:$C$212,$C23,Rótulos!$H$5:$H$212,$D23,Rótulos!$I$5:$I$212,$E23,Rótulos!$F$5:$F$212,"B2C") -> 0 | I23: =SUMIFS(Rótulos!$G$5:$G$212,Rótulos!$A$5:$A$212,$A23,Rótulos!$B$5:$B$212,$B23,Rótulos!$C$5:$C$212,$C23,Rótulos!$H$5:$H$212,$D23,Rótulos!$I$5:$I$212,$E23,Rótulos!$F$5:$F$212,"B2B") -> 14 | J23: =H23+I23 -> 14
A24: Bamboo | B24: Fragrância Concentrada | C24: 1000 | D24: Vinil ou Bopp | E24: 28 x 10,5 cm | F24: Fragrância Concentrada | G24: B2B | H24: =SUMIFS(Rótulos!$G$5:$G$212,Rótulos!$A$5:$A$212,$A24,Rótulos!$B$5:$B$212,$B24,Rótulos!$C$5:$C$212,$C24,Rótulos!$H$5:$H$212,$D24,Rótulos!$I$5:$I$212,$E24,Rótulos!$F$5:$F$212,"B2C") -> 0 | I24: =SUMIFS(Rótulos!$G$5:$G$212,Rótulos!$A$5:$A$212,$A24,Rótulos!$B$5:$B$212,$B24,Rótulos!$C$5:$C$212,$C24,Rótulos!$H$5:$H$212,$D24,Rótulos!$I$5:$I$212,$E24,Rótulos!$F$5:$F$212,"B2B") -> 6 | J24: =H24+I24 -> 6
A25: Bamboo | B25: Fragrância Ultra Concentrada | C25: 100 | D25: Vinil ou Bopp | E25: 13 x 5 cm | F25: Fragrância Ultra Concentrada | G25: B2B | H25: =SUMIFS(Rótulos!$G$5:$G$212,Rótulos!$A$5:$A$212,$A25,Rótulos!$B$5:$B$212,$B25,Rótulos!$C$5:$C$212,$C25,Rótulos!$H$5:$H$212,$D25,Rótulos!$I$5:$I$212,$E25,Rótulos!$F$5:$F$212,"B2C") -> 0 | I25: =SUMIFS(Rótulos!$G$5:$G$212,Rótulos!$A$5:$A$212,$A25,Rótulos!$B$5:$B$212,$B25,Rótulos!$C$5:$C$212,$C25,Rótulos!$H$5:$H$212,$D25,Rótulos!$I$5:$I$212,$E25,Rótulos!$F$5:$F$212,"B2B") -> 37 | J25: =H25+I25 -> 37
A26: Bamboo | B26: Fragrância Ultra Concentrada | C26: 500 | D26: Vinil ou Bopp | E26: 22 x 8 cm | F26: Fragrância Ultra Concentrada | G26: B2B | H26: =SUMIFS(Rótulos!$G$5:$G$212,Rótulos!$A$5:$A$212,$A26,Rótulos!$B$5:$B$212,$B26,Rótulos!$C$5:$C$212,$C26,Rótulos!$H$5:$H$212,$D26,Rótulos!$I$5:$I$212,$E26,Rótulos!$F$5:$F$212,"B2C") -> 0 | I26: =SUMIFS(Rótulos!$G$5:$G$212,Rótulos!$A$5:$A$212,$A26,Rótulos!$B$5:$B$212,$B26,Rótulos!$C$5:$C$212,$C26,Rótulos!$H$5:$H$212,$D26,Rótulos!$I$5:$I$212,$E26,Rótulos!$F$5:$F$212,"B2B") -> 43 | J26: =H26+I26 -> 43
A27: Bamboo | B27: Fragrância Ultra Concentrada | C27: 1000 | D27: Vinil ou Bopp | E27: 28 x 10,5 cm | F27: Fragrância Ultra Concentrada | G27: B2B | H27: =SUMIFS(Rótulos!$G$5:$G$212,Rótulos!$A$5:$A$212,$A27,Rótulos!$B$5:$B$212,$B27,Rótulos!$C$5:$C$212,$C27,Rótulos!$H$5:$H$212,$D27,Rótulos!$I$5:$I$212,$E27,Rótulos!$F$5:$F$212,"B2C") -> 0 | I27: =SUMIFS(Rótulos!$G$5:$G$212,Rótulos!$A$5:$A$212,$A27,Rótulos!$B$5:$B$212,$B27,Rótulos!$C$5:$C$212,$C27,Rótulos!$H$5:$H$212,$D27,Rótulos!$I$5:$I$212,$E27,Rótulos!$F$5:$F$212,"B2B") -> 4 | J27: =H27+I27 -> 4
A28: Bamboo | B28: Perfume para Ambientes | C28: 250 | D28: Vinil ou Bopp | E28: 18 x 6,5 cm | F28: Perfume para Ambientes + Perfume de Ambientes – Refil PET | G28: B2B e B2C | H28: =SUMIFS(Rótulos!$G$5:$G$212,Rótulos!$A$5:$A$212,$A28,Rótulos!$B$5:$B$212,$B28,Rótulos!$C$5:$C$212,$C28,Rótulos!$H$5:$H$212,$D28,Rótulos!$I$5:$I$212,$E28,Rótulos!$F$5:$F$212,"B2C") -> 2 | I28: =SUMIFS(Rótulos!$G$5:$G$212,Rótulos!$A$5:$A$212,$A28,Rótulos!$B$5:$B$212,$B28,Rótulos!$C$5:$C$212,$C28,Rótulos!$H$5:$H$212,$D28,Rótulos!$I$5:$I$212,$E28,Rótulos!$F$5:$F$212,"B2B") -> 36 | J28: =H28+I28 -> 38
A29: Bamboo | B29: Aromatizador de Ambientes | C29: 15 | D29: Transparente | E29: 6,5 x 5 cm | F29: Mini Aromatizador | G29: B2C | H29: =SUMIFS(Rótulos!$G$5:$G$212,Rótulos!$A$5:$A$212,$A29,Rótulos!$B$5:$B$212,$B29,Rótulos!$C$5:$C$212,$C29,Rótulos!$H$5:$H$212,$D29,Rótulos!$I$5:$I$212,$E29,Rótulos!$F$5:$F$212,"B2C") -> 100 | I29: =SUMIFS(Rótulos!$G$5:$G$212,Rótulos!$A$5:$A$212,$A29,Rótulos!$B$5:$B$212,$B29,Rótulos!$C$5:$C$212,$C29,Rótulos!$H$5:$H$212,$D29,Rótulos!$I$5:$I$212,$E29,Rótulos!$F$5:$F$212,"B2B") -> 0 | J29: =H29+I29 -> 100
A30: Bamboo | B30: Aromatizador de Ambientes | C30: 500 | D30: Vinil ou Bopp | E30: 22 x 8 cm | F30: Aromatizador (Refil) | G30: B2C | H30: =SUMIFS(Rótulos!$G$5:$G$212,Rótulos!$A$5:$A$212,$A30,Rótulos!$B$5:$B$212,$B30,Rótulos!$C$5:$C$212,$C30,Rótulos!$H$5:$H$212,$D30,Rótulos!$I$5:$I$212,$E30,Rótulos!$F$5:$F$212,"B2C") -> 10 | I30: =SUMIFS(Rótulos!$G$5:$G$212,Rótulos!$A$5:$A$212,$A30,Rótulos!$B$5:$B$212,$B30,Rótulos!$C$5:$C$212,$C30,Rótulos!$H$5:$H$212,$D30,Rótulos!$I$5:$I$212,$E30,Rótulos!$F$5:$F$212,"B2B") -> 0 | J30: =H30+I30 -> 10
A31: Bamboo | B31: Fragrância Concentrada | C31: 15 | D31: Transparente | E31: 6,5 x 5 cm | F31: Fragrância Concentrada (Refil Equipamento) | G31: B2C | H31: =SUMIFS(Rótulos!$G$5:$G$212,Rótulos!$A$5:$A$212,$A31,Rótulos!$B$5:$B$212,$B31,Rótulos!$C$5:$C$212,$C31,Rótulos!$H$5:$H$212,$D31,Rótulos!$I$5:$I$212,$E31,Rótulos!$F$5:$F$212,"B2C") -> 100 | I31: =SUMIFS(Rótulos!$G$5:$G$212,Rótulos!$A$5:$A$212,$A31,Rótulos!$B$5:$B$212,$B31,Rótulos!$C$5:$C$212,$C31,Rótulos!$H$5:$H$212,$D31,Rótulos!$I$5:$I$212,$E31,Rótulos!$F$5:$F$212,"B2B") -> 0 | J31: =H31+I31 -> 100
A32: Bamboo | B32: Fragrância Concentrada | C32: 100 | D32: Vinil ou Bopp | E32: 13 x 5 cm | F32: Fragrância Concentrada (Refil Equipamento) | G32: B2C | H32: =SUMIFS(Rótulos!$G$5:$G$212,Rótulos!$A$5:$A$212,$A32,Rótulos!$B$5:$B$212,$B32,Rótulos!$C$5:$C$212,$C32,Rótulos!$H$5:$H$212,$D32,Rótulos!$I$5:$I$212,$E32,Rótulos!$F$5:$F$212,"B2C") -> 30 | I32: =SUMIFS(Rótulos!$G$5:$G$212,Rótulos!$A$5:$A$212,$A32,Rótulos!$B$5:$B$212,$B32,Rótulos!$C$5:$C$212,$C32,Rótulos!$H$5:$H$212,$D32,Rótulos!$I$5:$I$212,$E32,Rótulos!$F$5:$F$212,"B2B") -> 0 | J32: =H32+I32 -> 30
A33: Bamboo | B33: Perfume para Ambientes | C33: 250 | D33: Transparente | E33: 5 x 10 cm (frente e verso) | F33: Perfume de Ambientes – Kit Varetas + Perfume de Ambientes – Válvula Spray | G33: B2C | H33: =SUMIFS(Rótulos!$G$5:$G$212,Rótulos!$A$5:$A$212,$A33,Rótulos!$B$5:$B$212,$B33,Rótulos!$C$5:$C$212,$C33,Rótulos!$H$5:$H$212,$D33,Rótulos!$I$5:$I$212,$E33,Rótulos!$F$5:$F$212,"B2C") -> 16 | I33: =SUMIFS(Rótulos!$G$5:$G$212,Rótulos!$A$5:$A$212,$A33,Rótulos!$B$5:$B$212,$B33,Rótulos!$C$5:$C$212,$C33,Rótulos!$H$5:$H$212,$D33,Rótulos!$I$5:$I$212,$E33,Rótulos!$F$5:$F$212,"B2B") -> 0 | J33: =H33+I33 -> 16
A34: Bergamota | B34: Fragrância Ultra Concentrada | C34: 100 | D34: Vinil ou Bopp | E34: 13 x 5 cm | F34: Fragrância Ultra Concentrada | G34: B2B | H34: =SUMIFS(Rótulos!$G$5:$G$212,Rótulos!$A$5:$A$212,$A34,Rótulos!$B$5:$B$212,$B34,Rótulos!$C$5:$C$212,$C34,Rótulos!$H$5:$H$212,$D34,Rótulos!$I$5:$I$212,$E34,Rótulos!$F$5:$F$212,"B2C") -> 0 | I34: =SUMIFS(Rótulos!$G$5:$G$212,Rótulos!$A$5:$A$212,$A34,Rótulos!$B$5:$B$212,$B34,Rótulos!$C$5:$C$212,$C34,Rótulos!$H$5:$H$212,$D34,Rótulos!$I$5:$I$212,$E34,Rótulos!$F$5:$F$212,"B2B") -> 8 | J34: =H34+I34 -> 8
... A55: Citric Bath | B55: Fragrância Concentrada | C55: 1000 | D55: Vinil ou Bopp | E55: 28 x 10,5 cm | F55: Fragrância Concentrada | G55: B2B | H55: =SUMIFS(Rótulos!$G$5:$G$212,Rótulos!$A$5:$A$212,$A55,Rótulos!$B$5:$B$212,$B55,Rótulos!$C$5:$C$212,$C55,Rótulos!$H$5:$H$212,$D55,Rótulos!$I$5:$I$212,$E55,Rótulos!$F$5:$F$212,"B2C") -> 0 | I55: =SUMIFS(Rótulos!$G$5:$G$212,Rótulos!$A$5:$A$212,$A55,Rótulos!$B$5:$B$212,$B55,Rótulos!$C$5:$C$212,$C55,Rótulos!$H$5:$H$212,$D55,Rótulos!$I$5:$I$212,$E55,Rótulos!$F$5:$F$212,"B2B") -> 18 | J55: =H55+I55 -> 18
A56: Citric Bath | B56: Fragrância Concentrada | C56: 5000 | D56: Vinil ou Bopp | E56: A definir | F56: Fragrância Concentrada | G56: B2B | H56: =SUMIFS(Rótulos!$G$5:$G$212,Rótulos!$A$5:$A$212,$A56,Rótulos!$B$5:$B$212,$B56,Rótulos!$C$5:$C$212,$C56,Rótulos!$H$5:$H$212,$D56,Rótulos!$I$5:$I$212,"=",Rótulos!$F$5:$F$212,"B2C") -> 0 | I56: =SUMIFS(Rótulos!$G$5:$G$212,Rótulos!$A$5:$A$212,$A56,Rótulos!$B$5:$B$212,$B56,Rótulos!$C$5:$C$212,$C56,Rótulos!$H$5:$H$212,$D56,Rótulos!$I$5:$I$212,"=",Rótulos!$F$5:$F$212,"B2B") -> 8 | J56: =H56+I56 -> 8
A57: Citrus Flowers | B57: Fragrância Concentrada | C57: 400 | D57: Vinil ou Bopp | E57: 22 x 8 cm | F57: Fragrância Concentrada | G57: B2B | H57: =SUMIFS(Rótulos!$G$5:$G$212,Rótulos!$A$5:$A$212,$A57,Rótulos!$B$5:$B$212,$B57,Rótulos!$C$5:$C$212,$C57,Rótulos!$H$5:$H$212,$D57,Rótulos!$I$5:$I$212,$E57,Rótulos!$F$5:$F$212,"B2C") -> 0 | I57: =SUMIFS(Rótulos!$G$5:$G$212,Rótulos!$A$5:$A$212,$A57,Rótulos!$B$5:$B$212,$B57,Rótulos!$C$5:$C$212,$C57,Rótulos!$H$5:$H$212,$D57,Rótulos!$I$5:$I$212,$E57,Rótulos!$F$5:$F$212,"B2B") -> 24 | J57: =H57+I57 -> 24
A58: Citrus Flowers | B58: Fragrância Concentrada | C58: 1000 | D58: Vinil ou Bopp | E58: 28 x 10,5 cm | F58: Fragrância Concentrada | G58: B2B | H58: =SUMIFS(Rótulos!$G$5:$G$212,Rótulos!$A$5:$A$212,$A58,Rótulos!$B$5:$B$212,$B58,Rótulos!$C$5:$C$212,$C58,Rótulos!$H$5:$H$212,$D58,Rótulos!$I$5:$I$212,$E58,Rótulos!$F$5:$F$212,"B2C") -> 0 | I58: =SUMIFS(Rótulos!$G$5:$G$212,Rótulos!$A$5:$A$212,$A58,Rótulos!$B$5:$B$212,$B58,Rótulos!$C$5:$C$212,$C58,Rótulos!$H$5:$H$212,$D58,Rótulos!$I$5:$I$212,$E58,Rótulos!$F$5:$F$212,"B2B") -> 8 | J58: =H58+I58 -> 8
A59: Citrus Flowers | B59: Fragrância Ultra Concentrada | C59: 100 | D59: Vinil ou Bopp | E59: 13 x 5 cm | F59: Fragrância Ultra Concentrada | G59: B2B | H59: =SUMIFS(Rótulos!$G$5:$G$212,Rótulos!$A$5:$A$212,$A59,Rótulos!$B$5:$B$212,$B59,Rótulos!$C$5:$C$212,$C59,Rótulos!$H$5:$H$212,$D59,Rótulos!$I$5:$I$212,$E59,Rótulos!$F$5:$F$212,"B2C") -> 0 | I59: =SUMIFS(Rótulos!$G$5:$G$212,Rótulos!$A$5:$A$212,$A59,Rótulos!$B$5:$B$212,$B59,Rótulos!$C$5:$C$212,$C59,Rótulos!$H$5:$H$212,$D59,Rótulos!$I$5:$I$212,$E59,Rótulos!$F$5:$F$212,"B2B") -> 16 | J59: =H59+I59 -> 16
A60: Citrus Flowers | B60: Fragrância Ultra Concentrada | C60: 500 | D60: Vinil ou Bopp | E60: 22 x 8 cm | F60: Fragrância Ultra Concentrada | G60: B2B | H60: =SUMIFS(Rótulos!$G$5:$G$212,Rótulos!$A$5:$A$212,$A60,Rótulos!$B$5:$B$212,$B60,Rótulos!$C$5:$C$212,$C60,Rótulos!$H$5:$H$212,$D60,Rótulos!$I$5:$I$212,$E60,Rótulos!$F$5:$F$212,"B2C") -> 0 | I60: =SUMIFS(Rótulos!$G$5:$G$212,Rótulos!$A$5:$A$212,$A60,Rótulos!$B$5:$B$212,$B60,Rótulos!$C$5:$C$212,$C60,Rótulos!$H$5:$H$212,$D60,Rótulos!$I$5:$I$212,$E60,Rótulos!$F$5:$F$212,"B2B") -> 13 | J60: =H60+I60 -> 13
A61: Citrus Flowers | B61: Perfume para Ambientes | C61: 500 | D61: Vinil ou Bopp | E61: 22 x 8 cm | F61: Perfume para Ambientes | G61: B2B | H61: =SUMIFS(Rótulos!$G$5:$G$212,Rótulos!$A$5:$A$212,$A61,Rótulos!$B$5:$B$212,$B61,Rótulos!$C$5:$C$212,$C61,Rótulos!$H$5:$H$212,$D61,Rótulos!$I$5:$I$212,$E61,Rótulos!$F$5:$F$212,"B2C") -> 0 | I61: =SUMIFS(Rótulos!$G$5:$G$212,Rótulos!$A$5:$A$212,$A61,Rótulos!$B$5:$B$212,$B61,Rótulos!$C$5:$C$212,$C61,Rótulos!$H$5:$H$212,$D61,Rótulos!$I$5:$I$212,$E61,Rótulos!$F$5:$F$212,"B2B") -> 16 | J61: =H61+I61 -> 16
...

Sheet Resumo por Tipo
A1: Quantidade de rótulos por tipo, volume e tamanho
A2: Fórmulas sobre a aba Rótulos. Tamanho vazio = "A definir".
A4: Tipo de rótulo | B4: Volume (ml) | C4: Tamanho | D4: Nº linhas | E4: B2C | F4: B2B | G4: Total
A5: Transparente | B5: 15 | C5: 6,5 x 5 cm | D5: =COUNTIFS(Rótulos!$H$5:$H$212,$A5,Rótulos!$C$5:$C$212,$B5,Rótulos!$I$5:$I$212,$C5) -> 24 | E5: =SUMIFS(Rótulos!$G$5:$G$212,Rótulos!$H$5:$H$212,$A5,Rótulos!$C$5:$C$212,$B5,Rótulos!$I$5:$I$212,$C5,Rótulos!$F$5:$F$212,"B2C") -> 3400 | F5: =SUMIFS(Rótulos!$G$5:$G$212,Rótulos!$H$5:$H$212,$A5,Rótulos!$C$5:$C$212,$B5,Rótulos!$I$5:$I$212,$C5,Rótulos!$F$5:$F$212,"B2B") -> 0 | G5: =E5+F5 -> 3400
A6: Transparente | B6: 250 | C6: 5 x 10 cm (frente e verso) | D6: =COUNTIFS(Rótulos!$H$5:$H$212,$A6,Rótulos!$C$5:$C$212,$B6,Rótulos!$I$5:$I$212,$C6) -> 34 | E6: =SUMIFS(Rótulos!$G$5:$G$212,Rótulos!$H$5:$H$212,$A6,Rótulos!$C$5:$C$212,$B6,Rótulos!$I$5:$I$212,$C6,Rótulos!$F$5:$F$212,"B2C") -> 472 | F6: =SUMIFS(Rótulos!$G$5:$G$212,Rótulos!$H$5:$H$212,$A6,Rótulos!$C$5:$C$212,$B6,Rótulos!$I$5:$I$212,$C6,Rótulos!$F$5:$F$212,"B2B") -> 0 | G6: =E6+F6 -> 472
A7: Vinil ou Bopp | B7: 100 | C7: 13 x 5 cm | D7: =COUNTIFS(Rótulos!$H$5:$H$212,$A7,Rótulos!$C$5:$C$212,$B7,Rótulos!$I$5:$I$212,$C7) -> 31 | E7: =SUMIFS(Rótulos!$G$5:$G$212,Rótulos!$H$5:$H$212,$A7,Rótulos!$C$5:$C$212,$B7,Rótulos!$I$5:$I$212,$C7,Rótulos!$F$5:$F$212,"B2C") -> 360 | F7: =SUMIFS(Rótulos!$G$5:$G$212,Rótulos!$H$5:$H$212,$A7,Rótulos!$C$5:$C$212,$B7,Rótulos!$I$5:$I$212,$C7,Rótulos!$F$5:$F$212,"B2B") -> 1307 | G7: =E7+F7 -> 1667
A8: Vinil ou Bopp | B8: 150 | C8: 18 x 6,5 cm | D8: =COUNTIFS(Rótulos!$H$5:$H$212,$A8,Rótulos!$C$5:$C$212,$B8,Rótulos!$I$5:$I$212,$C8) -> 6 | E8: =SUMIFS(Rótulos!$G$5:$G$212,Rótulos!$H$5:$H$212,$A8,Rótulos!$C$5:$C$212,$B8,Rótulos!$I$5:$I$212,$C8,Rótulos!$F$5:$F$212,"B2C") -> 0 | F8: =SUMIFS(Rótulos!$G$5:$G$212,Rótulos!$H$5:$H$212,$A8,Rótulos!$C$5:$C$212,$B8,Rótulos!$I$5:$I$212,$C8,Rótulos!$F$5:$F$212,"B2B") -> 63 | G8: =E8+F8 -> 63
A9: Vinil ou Bopp | B9: 160 | C9: A definir | D9: =SUMPRODUCT((Rótulos!$I$5:$I$212="")*(Rótulos!$H$5:$H$212=$A9)*(Rótulos!$C$5:$C$212=$B9)) -> 6 | E9: =SUMIFS(Rótulos!$G$5:$G$212,Rótulos!$H$5:$H$212,$A9,Rótulos!$C$5:$C$212,$B9,Rótulos!$I$5:$I$212,"=",Rótulos!$F$5:$F$212,"B2C") -> 0 | F9: =SUMIFS(Rótulos!$G$5:$G$212,Rótulos!$H$5:$H$212,$A9,Rótulos!$C$5:$C$212,$B9,Rótulos!$I$5:$I$212,"=",Rótulos!$F$5:$F$212,"B2B") -> 95 | G9: =E9+F9 -> 95
A10: Vinil ou Bopp | B10: 200 | C10: A definir | D10: =SUMPRODUCT((Rótulos!$I$5:$I$212="")*(Rótulos!$H$5:$H$212=$A10)*(Rótulos!$C$5:$C$212=$B10)) -> 1 | E10: =SUMIFS(Rótulos!$G$5:$G$212,Rótulos!$H$5:$H$212,$A10,Rótulos!$C$5:$C$212,$B10,Rótulos!$I$5:$I$212,"=",Rótulos!$F$5:$F$212,"B2C") -> 0 | F10: =SUMIFS(Rótulos!$G$5:$G$212,Rótulos!$H$5:$H$212,$A10,Rótulos!$C$5:$C$212,$B10,Rótulos!$I$5:$I$212,"=",Rótulos!$F$5:$F$212,"B2B") -> 2 | G10: =E10+F10 -> 2
A11: Vinil ou Bopp | B11: 250 | C11: 18 x 6,5 cm | D11: =COUNTIFS(Rótulos!$H$5:$H$212,$A11,Rótulos!$C$5:$C$212,$B11,Rótulos!$I$5:$I$212,$C11) -> 24 | E11: =SUMIFS(Rótulos!$G$5:$G$212,Rótulos!$H$5:$H$212,$A11,Rótulos!$C$5:$C$212,$B11,Rótulos!$I$5:$I$212,$C11,Rótulos!$F$5:$F$212,"B2C") -> 134 | F11: =SUMIFS(Rótulos!$G$5:$G$212,Rótulos!$H$5:$H$212,$A11,Rótulos!$C$5:$C$212,$B11,Rótulos!$I$5:$I$212,$C11,Rótulos!$F$5:$F$212,"B2B") -> 534 | G11: =E11+F11 -> 668
A12: Vinil ou Bopp | B12: 400 | C12: 22 x 8 cm | D12: =COUNTIFS(Rótulos!$H$5:$H$212,$A12,Rótulos!$C$5:$C$212,$B12,Rótulos!$I$5:$I$212,$C12) -> 26 | E12: =SUMIFS(Rótulos!$G$5:$G$212,Rótulos!$H$5:$H$212,$A12,Rótulos!$C$5:$C$212,$B12,Rótulos!$I$5:$I$212,$C12,Rótulos!$F$5:$F$212,"B2C") -> 0 | F12: =SUMIFS(Rótulos!$G$5:$G$212,Rótulos!$H$5:$H$212,$A12,Rótulos!$C$5:$C$212,$B12,Rótulos!$I$5:$I$212,$C12,Rótulos!$F$5:$F$212,"B2B") -> 635 | G12: =E12+F12 -> 635
A13: Vinil ou Bopp | B13: 500 | C13: 22 x 8 cm | D13: =COUNTIFS(Rótulos!$H$5:$H$212,$A13,Rótulos!$C$5:$C$212,$B13,Rótulos!$I$5:$I$212,$C13) -> 35 | E13: =SUMIFS(Rótulos!$G$5:$G$212,Rótulos!$H$5:$H$212,$A13,Rótulos!$C$5:$C$212,$B13,Rótulos!$I$5:$I$212,$C13,Rótulos!$F$5:$F$212,"B2C") -> 70 | F13: =SUMIFS(Rótulos!$G$5:$G$212,Rótulos!$H$5:$H$212,$A13,Rótulos!$C$5:$C$212,$B13,Rótulos!$I$5:$I$212,$C13,Rótulos!$F$5:$F$212,"B2B") -> 1019 | G13: =E13+F13 -> 1089
A14: Vinil ou Bopp | B14: 1000 | C14: 28 x 10,5 cm | D14: =COUNTIFS(Rótulos!$H$5:$H$212,$A14,Rótulos!$C$5:$C$212,$B14,Rótulos!$I$5:$I$212,$C14) -> 18 | E14: =SUMIFS(Rótulos!$G$5:$G$212,Rótulos!$H$5:$H$212,$A14,Rótulos!$C$5:$C$212,$B14,Rótulos!$I$5:$I$212,$C14,Rótulos!$F$5:$F$212,"B2C") -> 0 | F14: =SUMIFS(Rótulos!$G$5:$G$212,Rótulos!$H$5:$H$212,$A14,Rótulos!$C$5:$C$212,$B14,Rótulos!$I$5:$I$212,$C14,Rótulos!$F$5:$F$212,"B2B") -> 197 | G14: =E14+F14 -> 197
A15: Vinil ou Bopp | B15: 5000 | C15: A definir | D15: =SUMPRODUCT((Rótulos!$I$5:$I$212="")*(Rótulos!$H$5:$H$212=$A15)*(Rótulos!$C$5:$C$212=$B15)) -> 3 | E15: =SUMIFS(Rótulos!$G$5:$G$212,Rótulos!$H$5:$H$212,$A15,Rótulos!$C$5:$C$212,$B15,Rótulos!$I$5:$I$212,"=",Rótulos!$F$5:$F$212,"B2C") -> 0 | F15: =SUMIFS(Rótulos!$G$5:$G$212,Rótulos!$H$5:$H$212,$A15,Rótulos!$C$5:$C$212,$B15,Rótulos!$I$5:$I$212,"=",Rótulos!$F$5:$F$212,"B2B") -> 44 | G15: =E15+F15 -> 44
A16: Total | D16: =SUM(D5:D15) -> 208 | E16: =SUM(E5:E15) -> 4436 | F16: =SUM(F5:F15) -> 3896 | G16: =SUM(G5:G15) -> 8332
A18: Por tamanho (todos os tipos)
A19: Tamanho | B19: Tipo de rótulo | C19: Nº linhas | D19: B2C | E19: B2B | F19: Total
A20: 13 x 5 cm | B20: Vinil ou Bopp | C20: =COUNTIFS(Rótulos!$I$5:$I$212,$A20,Rótulos!$H$5:$H$212,$B20) -> 31 | D20: =SUMIFS(Rótulos!$G$5:$G$212,Rótulos!$I$5:$I$212,$A20,Rótulos!$H$5:$H$212,$B20,Rótulos!$F$5:$F$212,"B2C") -> 360 | E20: =SUMIFS(Rótulos!$G$5:$G$212,Rótulos!$I$5:$I$212,$A20,Rótulos!$H$5:$H$212,$B20,Rótulos!$F$5:$F$212,"B2B") -> 1307 | F20: =D20+E20 -> 1667
A21: 18 x 6,5 cm | B21: Vinil ou Bopp | C21: =COUNTIFS(Rótulos!$I$5:$I$212,$A21,Rótulos!$H$5:$H$212,$B21) -> 30 | D21: =SUMIFS(Rótulos!$G$5:$G$212,Rótulos!$I$5:$I$212,$A21,Rótulos!$H$5:$H$212,$B21,Rótulos!$F$5:$F$212,"B2C") -> 134 | E21: =SUMIFS(Rótulos!$G$5:$G$212,Rótulos!$I$5:$I$212,$A21,Rótulos!$H$5:$H$212,$B21,Rótulos!$F$5:$F$212,"B2B") -> 597 | F21: =D21+E21 -> 731
A22: 22 x 8 cm | B22: Vinil ou Bopp | C22: =COUNTIFS(Rótulos!$I$5:$I$212,$A22,Rótulos!$H$5:$H$212,$B22) -> 61 | D22: =SUMIFS(Rótulos!$G$5:$G$212,Rótulos!$I$5:$I$212,$A22,Rótulos!$H$5:$H$212,$B22,Rótulos!$F$5:$F$212,"B2C") -> 70 | E22: =SUMIFS(Rótulos!$G$5:$G$212,Rótulos!$I$5:$I$212,$A22,Rótulos!$H$5:$H$212,$B22,Rótulos!$F$5:$F$212,"B2B") -> 1654 | F22: =D22+E22 -> 1724
A23: 28 x 10,5 cm | B23: Vinil ou Bopp | C23: =COUNTIFS(Rótulos!$I$5:$I$212,$A23,Rótulos!$H$5:$H$212,$B23) -> 18 | D23: =SUMIFS(Rótulos!$G$5:$G$212,Rótulos!$I$5:$I$212,$A23,Rótulos!$H$5:$H$212,$B23,Rótulos!$F$5:$F$212,"B2C") -> 0 | E23: =SUMIFS(Rótulos!$G$5:$G$212,Rótulos!$I$5:$I$212,$A23,Rótulos!$H$5:$H$212,$B23,Rótulos!$F$5:$F$212,"B2B") -> 197 | F23: =D23+E23 -> 197
A24: 5 x 10 cm (frente e verso) | B24: Transparente | C24: =COUNTIFS(Rótulos!$I$5:$I$212,$A24,Rótulos!$H$5:$H$212,$B24) -> 34 | D24: =SUMIFS(Rótulos!$G$5:$G$212,Rótulos!$I$5:$I$212,$A24,Rótulos!$H$5:$H$212,$B24,Rótulos!$F$5:$F$212,"B2C") -> 472 | E24: =SUMIFS(Rótulos!$G$5:$G$212,Rótulos!$I$5:$I$212,$A24,Rótulos!$H$5:$H$212,$B24,Rótulos!$F$5:$F$212,"B2B") -> 0 | F24: =D24+E24 -> 472
A25: 6,5 x 5 cm | B25: Transparente | C25: =COUNTIFS(Rótulos!$I$5:$I$212,$A25,Rótulos!$H$5:$H$212,$B25) -> 24 | D25: =SUMIFS(Rótulos!$G$5:$G$212,Rótulos!$I$5:$I$212,$A25,Rótulos!$H$5:$H$212,$B25,Rótulos!$F$5:$F$212,"B2C") -> 3400 | E25: =SUMIFS(Rótulos!$G$5:$G$212,Rótulos!$I$5:$I$212,$A25,Rótulos!$H$5:$H$212,$B25,Rótulos!$F$5:$F$212,"B2B") -> 0 | F25: =D25+E25 -> 3400
A26: A definir | B26: Vinil ou Bopp | C26: =SUMPRODUCT((Rótulos!$I$5:$I$212="")*(Rótulos!$H$5:$H$212=$B26)) -> 10 | D26: =SUMIFS(Rótulos!$G$5:$G$212,Rótulos!$I$5:$I$212,"=",Rótulos!$H$5:$H$212,$B26,Rótulos!$F$5:$F$212,"B2C") -> 0 | E26: =SUMIFS(Rótulos!$G$5:$G$212,Rótulos!$I$5:$I$212,"=",Rótulos!$H$5:$H$212,$B26,Rótulos!$F$5:$F$212,"B2B") -> 141 | F26: =D26+E26 -> 141
A27: Total | C27: =SUM(C20:C26) -> 208 | D27: =SUM(D20:D26) -> 4436 | E27: =SUM(E20:E26) -> 3896 | F27: =SUM(F20:F26) -> 8332

Sheet B2B Antes x Depois
A1: B2B – quantidade anterior (Controle de Rótulos) × nova (relatório de remessas)
A2: Anterior = aba B2B - Volumes; nova = soma da coluna Qtd do relatório smartjvg.
A4: Fragrância | B4: Concentração | C4: Volume (ml) | D4: Qtd. anterior | E4: Qtd. nova | F4: Diferença
A5: Alecrim | B5: Fragrância Concentrada | C5: 160 | D5: 0 | E5: 29 | F5: =E5-D5 -> 29
A6: Alecrim | B6: Fragrância Concentrada | C6: 400 | D6: 0 | E6: 55 | F6: =E6-D6 -> 55
A7: Alecrim | B7: Fragrância Concentrada | C7: 1000 | D7: 0 | E7: 21 | F7: =E7-D7 -> 21
A8: Alecrim | B8: Fragrância Concentrada | C8: 5000 | D8: 0 | E8: 28 | F8: =E8-D8 -> 28
A9: Alecrim | B9: Fragrância Ultra Concentrada | C9: 100 | D9: 0 | E9: 19 | F9: =E9-D9 -> 19
A10: Alecrim | B10: Fragrância Ultra Concentrada | C10: 500 | D10: 0 | E10: 76 | F10: =E10-D10 -> 76
A11: Alecrim Sence | B11: Fragrância Concentrada | C11: 400 | D11: 0 | E11: 4 | F11: =E11-D11 -> 4
A12: Alecrim Sence | B12: Fragrância Concentrada | C12: 1000 | D12: 0 | E12: 15 | F12: =E12-D12 -> 15
A13: Alecrim Sence | B13: Fragrância Concentrada | C13: 5000 | D13: 0 | E13: 8 | F13: =E13-D13 -> 8
A14: Bamboo | B14: Fragrância Concentrada | C14: 400 | D14: 1 | E14: 14 | F14: =E14-D14 -> 13
A15: Bamboo | B15: Fragrância Concentrada | C15: 1000 | D15: 1 | E15: 6 | F15: =E15-D15 -> 5
A16: Bamboo | B16: Fragrância Ultra Concentrada | C16: 100 | D16: 4 | E16: 37 | F16: =E16-D16 -> 33
... A129: Verveine de Provence | B129: Fragrância Ultra Concentrada | C129: 100 | D129: 0 | E129: 48 | F129: =E129-D129 -> 48
A130: Total | D130: =SUM(D5:D129) -> 206 | E130: =SUM(E5:E129) -> 3896 | F130: =SUM(F5:F129) -> 3690
